[["/usr/local/lib/python3.10/dist-packages/exceptiongroup/__init__.py",[false,[["__all__",true,13,null],["catch",true,2,["catch","/usr/local/lib/python3.10/dist-packages/exceptiongroup/_catch.py",12]],["format_exception",true,2,["format_exception","/home/heitormesk/.vscode/extensions/ms-python.vscode-pylance-2023.11.10/dist/typeshed-fallback/stdlib/traceback.pyi",12]],["format_exception_only",true,2,["format_exception_only","/home/heitormesk/.vscode/extensions/ms-python.vscode-pylance-2023.11.10/dist/typeshed-fallback/stdlib/traceback.pyi",12]],["print_exc",true,2,["print_exc","/home/heitormesk/.vscode/extensions/ms-python.vscode-pylance-2023.11.10/dist/typeshed-fallback/stdlib/traceback.pyi",12]],["print_exception",true,2,["print_exception","/home/heitormesk/.vscode/extensions/ms-python.vscode-pylance-2023.11.10/dist/typeshed-fallback/stdlib/traceback.pyi",12]],["BaseExceptionGroup",true,13,null],["ExceptionGroup",true,13,null]]]]]